Failure # 1 (occurred at 2022-04-29_00-15-42)
Traceback (most recent call last):
  File "/home/ubuntu/.local/lib/python3.8/site-packages/ray/tune/ray_trial_executor.py", line 901, in get_next_executor_event
    future_result = ray.get(ready_future)
  File "/home/ubuntu/.local/lib/python3.8/site-packages/ray/_private/client_mode_hook.py", line 105, in wrapper
    return func(*args, **kwargs)
  File "/home/ubuntu/.local/lib/python3.8/site-packages/ray/worker.py", line 1809, in get
    raise value.as_instanceof_cause()
ray.exceptions.RayTaskError(TuneError): [36mray::ImplicitFunc.train()[39m (pid=54055, ip=192.168.2.213, repr=train)
  File "/home/ubuntu/.local/lib/python3.8/site-packages/ray/tune/trainable.py", line 349, in train
    result = self.step()
  File "/home/ubuntu/.local/lib/python3.8/site-packages/ray/tune/function_runner.py", line 403, in step
    self._report_thread_runner_error(block=True)
  File "/home/ubuntu/.local/lib/python3.8/site-packages/ray/tune/function_runner.py", line 567, in _report_thread_runner_error
    raise TuneError(
ray.tune.error.TuneError: Trial raised an exception. Traceback:
[36mray::ImplicitFunc.train()[39m (pid=54055, ip=192.168.2.213, repr=train)
  File "/home/ubuntu/.local/lib/python3.8/site-packages/ray/tune/function_runner.py", line 272, in run
    self._entrypoint()
  File "/home/ubuntu/.local/lib/python3.8/site-packages/ray/tune/function_runner.py", line 348, in entrypoint
    return self._trainable_func(
  File "/home/ubuntu/.local/lib/python3.8/site-packages/ray/tune/function_runner.py", line 640, in _trainable_func
    output = fn()
  File "/tmp/ipykernel_53229/2986979186.py", line 9, in train
AttributeError: module 'ray.tune' has no attribute 'reportm'

